Running: /home/work/dcvc/miniconda3/envs/dcvc_rt_env/bin/python test_video.py --model_path_i ./checkpoints/cvpr2025_image.pth.tar --model_path_p ./checkpoints/cvpr2025_video.pth.tar --rate_num 2 --test_config ./dataset_config_example_yuv420.json --cuda 0 -w 1 --write_stream 0 --save_decoded_frame 0 --force_zero_thres 0.12 --output_path output_smoke.json --force_intra_period -1 --reset_interval 64 --force_frame_num 2 --check_existing 0 --verbose 1
cannot import cuda implementation for inference, fallback to pytorch.
testing 2 rates, using qp: 0, 63, 
  0%|          | 0/106 [00:00<?, ?it/s]
cannot import cuda implementation for inference, fallback to pytorch.
  0%|          | 0/106 [00:04<?, ?it/s]
concurrent.futures.process._RemoteTraceback: 
"""
Traceback (most recent call last):
  File "/home/work/dcvc/miniconda3/envs/dcvc_rt_env/lib/python3.12/concurrent/futures/process.py", line 264, in _process_worker
    r = call_item.fn(*call_item.args, **call_item.kwargs)
        ^^^^^^^^^^^^^^^^^^^^^^^^^^^^^^^^^^^^^^^^^^^^^^^^^
  File "/home/work/dcvc/DCVC_fresh/test_video.py", line 360, in worker
    assert args['write_stream'], ""
           ~~~~^^^^^^^^^^^^^^^^
AssertionError
"""

The above exception was the direct cause of the following exception:

Traceback (most recent call last):
  File "/home/work/dcvc/DCVC_fresh/test_video.py", line 541, in <module>
    main()
  File "/home/work/dcvc/DCVC_fresh/test_video.py", line 514, in main
    result = obj.result()
             ^^^^^^^^^^^^
  File "/home/work/dcvc/miniconda3/envs/dcvc_rt_env/lib/python3.12/concurrent/futures/_base.py", line 456, in result
    return self.__get_result()
           ^^^^^^^^^^^^^^^^^^^
  File "/home/work/dcvc/miniconda3/envs/dcvc_rt_env/lib/python3.12/concurrent/futures/_base.py", line 401, in __get_result
    raise self._exception
AssertionError
Return code: 1
No output_smoke.json produced.
