Found existing installation: opencv-python 4.8.1.78
Uninstalling opencv-python-4.8.1.78:
ERROR: Exception:
Traceback (most recent call last):
  File "/usr/lib/python3.10/shutil.py", line 816, in move
    os.rename(src, real_dst)
PermissionError: [Errno 13] Permission denied: '/usr/local/lib/python3.10/dist-packages/cv2/Error/' -> '/tmp/pip-uninstall-rqjm05ty'

During handling of the above exception, another exception occurred:

Traceback (most recent call last):
  File "/usr/local/lib/python3.10/dist-packages/pip/_internal/cli/base_command.py", line 180, in exc_logging_wrapper
    status = run_func(*args)
  File "/usr/local/lib/python3.10/dist-packages/pip/_internal/commands/uninstall.py", line 105, in run
    uninstall_pathset = req.uninstall(
  File "/usr/local/lib/python3.10/dist-packages/pip/_internal/req/req_install.py", line 687, in uninstall
    uninstalled_pathset.remove(auto_confirm, verbose)
  File "/usr/local/lib/python3.10/dist-packages/pip/_internal/req/req_uninstall.py", line 381, in remove
    moved.stash(path)
  File "/usr/local/lib/python3.10/dist-packages/pip/_internal/req/req_uninstall.py", line 272, in stash
    renames(path, new_path)
  File "/usr/local/lib/python3.10/dist-packages/pip/_internal/utils/misc.py", line 315, in renames
    shutil.move(old, new)
  File "/usr/lib/python3.10/shutil.py", line 834, in move
    rmtree(src)
  File "/usr/lib/python3.10/shutil.py", line 725, in rmtree
    _rmtree_safe_fd(fd, path, onerror)
  File "/usr/lib/python3.10/shutil.py", line 681, in _rmtree_safe_fd
    onerror(os.unlink, fullname, sys.exc_info())
  File "/usr/lib/python3.10/shutil.py", line 679, in _rmtree_safe_fd
    os.unlink(entry.name, dir_fd=topfd)
PermissionError: [Errno 13] Permission denied: '__init__.pyi'

Usage:   
  /usr/bin/python -m pip uninstall [options] <package> ...
  /usr/bin/python -m pip uninstall [options] -r <requirements file> ...

no such option: --user
