---------------------------------------------------------------------------
NameError                                 Traceback (most recent call last)
Cell In[29], line 15
     13     print("IMPORT FAILED in subprocess. Full traceback:")
     14     traceback.print_exc()
---> 15 PY

NameError: name 'PY' is not defined
